Workbook
Name Z_0111E7B5_3E0B_11D4_8303_000102284B93_.wvu.PrintArea: #REF!
Name Z_011E7B5_3E0B_11D4_8303_000102284B94: #REF!
Name Z_EC51EC7F_3C0B_4CF9_8F20_C7FD08174DA8_.wvu.PrintArea: 'Entsorgung Déchets'!$B$1:$S$10
Name Z_EC51EC7F_3C0B_4CF9_8F20_C7FD08174DA8_.wvu.PrintArea: 'Gebäudetechnik Technique'!$B$1:$W$48
Name Z_EC51EC7F_3C0B_4CF9_8F20_C7FD08174DA8_.wvu.PrintArea: 'Baumaterialien Matériaux'!$B$1:$V$271
Name Z_011E7B5_3E0B_11D4_8303_000102284B94: #REF!
Name Z_EC51EC7F_3C0B_4CF9_8F20_C7FD08174DA8_.wvu.PrintArea: 'Energie Énergie'!$B$1:$L$95
Name Z_EC51EC7F_3C0B_4CF9_8F20_C7FD08174DA8_.wvu.PrintTitles: 'Erläuterung Explication'!$1:$2
Name Z_EC51EC7F_3C0B_4CF9_8F20_C7FD08174DA8_.wvu.PrintTitles: 'Energie Énergie'!$1:$7
Name Z_011E7B5_3E0B_11D4_8303_000102284B94: #REF!
Name Z_EC51EC7F_3C0B_4CF9_8F20_C7FD08174DA8_.wvu.PrintTitles: 'Transporte Transports'!$1:$9
Name Z_EC51EC7F_3C0B_4CF9_8F20_C7FD08174DA8_.wvu.PrintTitles: 'Entsorgung Déchets'!$1:$10
Name Z_0111E7B5_3E0B_11D4_8303_000102284B93_.wvu.PrintArea: #REF!
Name Z_0111E7B5_3E0B_11D4_8303_000102284B93_.wvu.PrintArea: #REF!
Name Z_EC51EC7F_3C0B_4CF9_8F20_C7FD08174DA8_.wvu.PrintTitles: 'Gebäudetechnik Technique'!$1:$9
Name Z_0111E7B5_3E0B_11D4_8303_000102284B93_.wvu.PrintArea: #REF!
Name Z_011E7B5_3E0B_11D4_8303_000102284B94: #REF!
Name Z_011E7B5_3E0B_11D4_8303_000102284B94: #REF!
Name Z_EC51EC7F_3C0B_4CF9_8F20_C7FD08174DA8_.wvu.PrintTitles: 'Baumaterialien Matériaux'!$1:$9
Name Z_0111E7B5_3E0B_11D4_8303_000102284B93_.wvu.PrintArea: #REF!
Name Z_0111E7B5_3E0B_11D4_8303_000102284B93_.wvu.PrintArea: #REF!
Name Z_011E7B5_3E0B_11D4_8303_000102284B94: #REF!
Name Z_EC51EC7F_3C0B_4CF9_8F20_C7FD08174DA8_.wvu.PrintArea: 'Transporte Transports'!$B$1:$Z$73
Name Z_0111E7B5_3E0B_11D4_8303_000102284B93_.wvu.PrintArea: #REF!
Name Z_0111E7B5_3E0B_11D4_8303_000102284B93_.wvu.PrintArea: #REF!
Name Z_EC51EC7F_3C0B_4CF9_8F20_C7FD08174DA8_.wvu.PrintArea: 'Erläuterung Explication'!$A$1:$D$18

Sheet Overview
A1: Overview
A3: This sheet transforms KBOB v5 into CSV so that it can be imported into the vyzn platform.
A5: 1. Open Sheet "Consolidated Energy"
A6: 2. Copy all contents to sheet "Import Energy" without formatting (ctrl+shift+v)
A7: 3. Go to sheet "Import Energy"
A8: 4. Delete all rows that are no actual records such as that subtexts, legends or explanations
A9: 5. Select all number columns, then choose Edit->Format->Number->Plain Text
A10: 6. Then choose Edit->Find and replace, then replace "," by ""
A11: 7. Click File->Download->CSV
A12: 8. Run vyzn-import-cli as follows:
A13: npx tsc && node dist/main.js import-products --input data/kbob_2022_v5_energy.csv --url https://dbs-gateway-service-dev.azurewebsites.net --auth data/auth.txt --category none
A14: 9 Repeat the same for the other tabs: transports, baumaterialien, gebäudetechnik, entsorgung
... A22: Be super careful when changing "Consolidated Gebäudtechnik" as it the rows contains gaps, so you can not simply update formulas accross all rows. To be improved.

Sheet RefDimensions
A1: Name | B1: EnumValue
A2: EBF | B2: energyReferenceArea
A3: Masse | B3: mass
A4: Sondenlänge | B4: probeLength
A5: Gerät | B5: device
A6: Kollektorfläche | B6: collectorArea
A7: Speicherkap. | B7: storageCapacity
A8: Max. Leistung | B8: maxPower
A9: Panelfläche | B9: panelArea
A10: Endenergie | B10: finalEnergy
A11: Nutzwärme | B11: usefulHeat
A12: Aushubvolumen | B12: excavationVolume
... A16: Nutzwärme2 | B16: usefulHeat

Sheet MepClassificationAndLifecycle
A1: Key | B1: vyzn.catalogue.ch.minergie.eco.MepClassification | C1: vyzn.catalogue.lifeCycle | E1: backported from KBOB 2022 v5
A2: 31.001 | B2: heatGeneration | C2: 20
A3: 31.002 | B3: heatGeneration | C3: 20
A4: 31.003 | B4: heatGeneration | C4: 20
A5: 31.027 | B5: heatGeneration | C5: 20
A6: 31.021 | B6: heatDistribution | C6: 30
A7: 31.022 | B7: heatDistribution | C7: 30
A8: 31.023 | B8: heatEmission | C8: 30
A9: 31.024 | B9: heatEmission | C9: 30
A10: 31.025 | B10: heatEmission | C10: 30
A11: 31.015 | B11: heatDistribution | C11: 30
A12: 31.016 | B12: geothermalProbe | C12: 40
A13: 31.026 | B13: heatGeneration | C13: 20
... A68: 34.036 | B68: photovoltaicSystem | C68: 30

Sheet Erläuterung  Explication
A1: Ökobilanzdaten im Baubereich KBOB / eco-bau / IPB 2009/1:2016 | D1: Données écobilans dans la construction
A3: Die Ökobilanz-Kennwerte wurden mit aktualisierten Hintergrunddaten (KBOB-Datenbestand 2016, basierend auf dem ecoinvent-Datenbestand v2.2) gerechnet. Neu wird in der pdf-Datei der Indikator "Primärenergie erneuerbar" anstelle des Indikators "Primärenergie, gesamt" aufgeführt. Zudem wurden die Sachbilanzen einzelner Baumaterialien (Durchschnitt und herstellerspezifische), Gebäudetechnikelemente, Energiesysteme und Transportsysteme aktualisiert beziehungsweise neu hinzugefügt. Legende: schwarz: aktualisierte Hintergrunddaten (Sachbilanzdaten unverändert) rot: - Zahlen in rot: Sachbilanz- und Hintergrunddaten bei bestehenden Datensätzen aktualisiert (z.B. ID-Nr. 06.001) - ganze Zeile rot: Datensatz neu in die KBOB-Ökobilanzdaten 2016 aufgenommen (z.B. ID-Nr. 00.001) blau schattiert (nur in der Excel-Datei verfügbar): hersteller- oder herstellerregionenspezifische Datensätze Sortierkriterien für die KBOB-Ökobilanzdaten 2016: 1. Gruppe gemäss vorderem Teil der ID-Nummer (z.B. ID-Nr. 06.xxx) 2. innerhalb Gruppe alphabetisch nach Name in deutscher Sprache | C3: Auf www.kbob.ch > Publikationen > Nachhaltiges Bauen, sind zwei Dateien platziert: Die pdf-Datei «Ökobilanzdaten im Baubereich 2009/1:2016» soll den Planenden den Einstieg in diese Thematik erleichtern. Sie enthält für die Schweiz repräsentative Daten für Baumaterialien und Gebäudetechnik (Herstellung, Entsorgung), Energie sowie Transporte (Betrieb, Fahrzeug, Infrastruktur). Die Excel-Datei «Ökobilanzdaten im Baubereich 2009/1:2016» enthält zusätzlich die Ergebnisse des Indikators "Primärenergie, gesamt", herstellerspezifische Daten sowie die Daten zu den bauspezifischen Entsorgungsprozessen. Die Excel-Datei wird in zwei Versionen angeboten, in denen die Primärenergie in MJ bzw. in kWh gezeigt wird. Ab 2017 wird nur noch die Einheit kWh verwendet. Die Excel-Datei stellt ein Arbeitsinstrument dar.
A4: Gesamtbewertung | B4: Teilbewertung
A5: UBP'13 | B5: Primärenergie (PE) | D5: Treibhausgasemissionen (THG-E)
B6: erneuerbar | C6: nicht erneuerbar (Graue Energie)
A7: Die Umweltbelastungspunkte 2013 (UBP'13) quantifizieren die Umweltbelastungen durch die Nutzung von Energie- und stofflichen Ressourcen, von Land und Süsswasser, durch Emissionen in Luft, Gewässer und Boden, durch die Ablagerung von Rückständen aus der Abfallbehandlung sowie durch Verkehrslärm. | B7: Die erneuerbare Primärenergie quantifiziert den kumulierten Energieaufwand der erneuerbaren Energieträger. Die erneuerbaren Energieträger umfassen Wasserkraft, Holz / Biomasse (ohne Kahlschlag von Primärwäldern), Sonnen-, Wind-, geothermische Energie und Umgebungswärme. Primärenergie erneuerbar und nicht erneuerbar bilden addiert die Primärenergie gesamt. | C7: Die nicht erneuerbare Primärenergie (Graue Energie) quantifiziert den kumulierten Energieaufwand der fossilen und nuklearen Energieträger sowie Holz aus Kahlschlag von Primärwäldern. Primärenergie erneuerbar und nicht erneuerbar bilden addiert die Primärenergie gesamt. | D7: Die Treibhausgasemissionen quantifizieren die kumulierten Wirkungen verschiedener Treibhausgase bezogen auf die Leitsubstanz CO2. Die Treibhauswirkung wird auf Basis der Treibhauspotenziale des 5. Sachstandberichts des IPCC (2013) quantifiziert.
A8: Die Umweltauswirkungen der Teilbewertungen sind in der Gesamtbewertung UBP enthalten. | B8: Diese Kenngrösse ist Teil der Betrachtung gemäss 2000 Watt Gesellschaft. Mit der Summe aus Primärenergie erneuerbar und nicht erneuerbar wird die dem Gebäude zugeführte Energiemenge (Endenergie) gemäss Merkblatt SIA 2031 «Energieausweis für Gebäude» bewertet. | C8: Mit dieser Kenngrösse wird die Bezugsgrösse gemäss Merkblatt SIA 2032 «Graue Energie von Gebäuden» und gemäss Merkblatt SIA 2040 „SIA-Effizienzpfad Gebäude“ bewertet. | D8: Mit dieser Kenngrösse werden die dem Gebäude zugeführte Energiemenge gemäss Merkblatt SIA 2031 «Energieausweis für Gebäude», die Bezugsgrösse gemäss Merkblatt SIA 2032 «Graue Energie von Gebäuden» sowie der Energieverbrauch gemäss Merkblatt SIA 2040 «Effizienzpfad Energie» bewertet.
A9: Die Beurteilung mit der Methode der ökologischen Knappheit zeigt in Umweltbelastungspunkten (UBP'13) ein vollständiges Bild der Umweltauswirkungen auf und basiert auf der Schweizerischen Umweltpolitik. Sie entspricht den Anforderungen eines „true and fair view“ bezüglich Umweltinformationen. | C9: Die nicht erneuerbare Primärenergie (Graue Energie) ist ein im Baubereich etablierter Kennwert. Die Instrumente des Vereins eco-bau (eco-devis, Eco-BKP-Merkblätter) stützen sich für eine gesamtheitliche Beurteilung neben zusätzlichen ökologischen Merkmalen auf diese Teilbewertung ab. | D9: Die in dieser Empfehlung ausgewiesenen Treibhausgasemissionen sind ein Kennwert für die Klimaerwärmung. Sie sind nicht gleichbedeutend mit dem standortgebundenen CO2-Ausstoss, welcher Gegenstand von Zielvereinbarungen zwischen Emittenten und der Eidgenossenschaft im Rahmen des CO2-Gesetzes ist.
A10: Ökobilanzen basieren auf Modellen, die von Wertvorstellungen geprägt sind. Somit sind die Ergebnisse nicht wertfrei. In dieser Empfehlung wurde für alle Materialien dieselbe Modellierungsmethode verwendet. Werden andere Modellierungsmethoden verwendet, können die Ergebnisse anders aussehen. Diese Informationen stammen aus zuverlässigen Quellen. Die Autoren oder ihre Organisationen lehnen jedoch jegliche Haftung für Schäden oder Verluste ab, die durch die Verwendung dieser Angaben entstehen könnten. Die Verantwortung für die Nutzung der Informationen liegt ausschliesslich bei den sie Verwendenden.
A11: Les valeurs relatives aux écobilans ont été calculées sur la base des données fondamentales actuelles (données 2016 de la KBOB fondées sur la base de données ecoinvent v2.2). L'indice «énergie primaire, renouvelable» remplace dorénavant l'indice «énergie primaire, totale» dans le fichier pdf. En outre, les données des écobilans de tous les matériaux (valeur moyenne et indice de fabrication), de la technique du bâtiment, de l'énergie, des transports et des déchets ont été mises à jour ou complétées. Légende: noir: données fondamentales actualisées (bilans inchangés) rouge: - chiffres en rouge: données fondamentales et données des écobilans actualisées pour les groupes de données existants (par ex. no ID 06.001). - toute la cellule en rouge: groupe de données ajouté à la liste (par ex. no ID 00.001) bleu: données spécifiques aux fabricants et aux régions de production (disponibles en format Excel uniquement) Critères de tri pour la liste des écobilans de la KBOB 2016: 1. groupes selon la première partie du no d'identification (par ex. no ID 06.xxx) 2. au sein des groupes, désignations en allemand par ordre alphabétique | C11: A l’adresse www.kbob.ch > Publications > Construction durable, se trouvent deux fichiers: Le fichier pdf «Données des écobilans dans la construction 2009/1:2016» doit permettre aux planificateurs de mieux aborder ce thème. Il contient des données pertinentes pour la Suisse sur les matériaux de construction et la technique du bâtiment (fabrication, élimination) ainsi que sur l'énergie et les transports (exploitation, véhicule, infrastructure). Le fichier excel «Liste Oekobilanzdaten im Baubereich 2009/1:2016» contient en outre des données concernant le fabricant ainsi que des données sur les processus d'élimination dans le domaine de la construction. Il sert d'instrument de travail.
A12: Evaluation globale | B12: Evaluation partielle
A13: UBP'13 | B13: Energie primaire | D13: Emissions de gaz à effet de serre
B14: renouvelable | C14: non renouvelable énergie grise
A15: Les Ecopoints (UBP) 2013 quantifient les charges environnementales résultant de l'utilisation des ressources matérielles et énergétiques, de la terre et de l'eau douce, des émissions dans l'air, l'eau et le sol, du dépôt de résidus découlant du traitement des déchêts ainsi que du bruit de la circulation. | B15: L'énergie primaire renouvelable indique l'énergie cumulée des sources renouvelables. Les sources d'énergie renouvelables comprennent la force hydraulique, le bois/la biomasse (sans déboisement de forêts primaires), l'énergie solaire, éolienne et géothermique ainsi que la chaleur ambiante. L'énergie primaire se compose de l'énergie primaire renouvelable et de l'énergie primaire non renouvelable. | C15: L'énergie non renouvelable (énergie grise) indique l'énergie cumulée de la consommation énergétique fossile et nucléaire ainsi que le bois issu du déboisement de forêts primaires. L'énergie primaire se compose de l'énergie primaire renouvelable et de l'énergie primaire non renouvelable. | D15: L'effet de serre évalue les effets cumulés de différents gaz à effet de serre par rapport à la substance principale qu'est le CO2. L'effet de serre est quantifié sur la base du potentiel de réchauffement évoqué dans le cinquième rapport d'évaluation (2013) du GIEC.
A16: Les répercussions sur l'environnement des évaluations partielles sont prises en compte dans l'évaluation globale UPB. | B16: Cette valeur fait partie des observations contenues dans le projet Société à 2000 watts. La consommation d'énergie du bâtiment (énergie finale) est évaluée conformément à la fiche technique SIA 2031 «Certificat énergétique des bâtiments». | C16: Cette valeur permet d'évaluer l'énergie grise selon la fiche technique SIA 2031 «Energie grise» et la fiche technique SIA 2040 «En route pour l'efficacité énergétique». | D16: Cette valeur permet d'évaluer la consommation totale d'un bâtiment selon la fiche technique SIA 2031 «Certificat énergétique des bâtiments», les émissions de gaz à effet de serre des matériaux selon la fiche technique SIA 2032 «Energie grise des bâtiments» ainsi que la consommation d'énergie selon la fiche technique SIA 2040 «La voie SIA vers l'efficacité énergétique».
A17: L'évaluation fondée sur la méthode de la raréfaction des ressources fournit une récapitulation complète des répercussions sur l'environnement à l'aide d'écopoints (UBP) et se fonde sur la politique environnementale suisse. Elle répond au principe de l'image fidèle («True and Fair View») en ce qui concerne l'information en matière d'environnement. | C17: L'énergie primaire non renouvelable (énergie grise) est une valeur connue dans la construction, elle est indiquée séparément. Plusieurs instruments de l'association eco-bau (eco-devis, feuilles CFC-Eco) s'appuient aujourd'hui, pour une évaluation générale, sur cette évaluation partielle, en plus des caractéristiques écologiques. | D17: L'effet de serre dont il est question dans la présente recommandation est un indice du réchauffement climatique. Il n'est pas comparable avec l'émission de CO2 liée à l'emplacement et dont les objectifs doivent être fixés, en relation avec la loi sur le CO2, dans le cadre d'une négociation entre les émetteurs et la Confédération.
A18: Les éco-bilans se fondent sur des modèles empreints de valeurs. Par conséquent, les résultats ne sont pas neutres. Dans la présente recommandation, tous les matériaux se basent sur la même méthode de modélisation. Si d'autres méthodes sont utilisées, les résultats peuvent différer. Ces informations ont été obtenues de sources jugées fiables. Toutefois, les auteurs ou leurs organisations déclinent toute responsabilité pour des dégâts ou pertes résultant de l'utilisation de celles-ci. Vous êtes entièrement responsables de l'utilisation de ces informations.

Sheet ImportBaumaterialien
A1: Name | B1: ProductKey | C1: Description | D1: Picture | E1: Product sections | F1: Type | G1: SubType | H1: hatchingPattern | I1: vyzn.catalogue.Density | J1: vyzn.catalogue.ch.KBOB2022.UBPTotal | K1: vyzn.catalogue.ch.KBOB2022.UBPProduction | L1: vyzn.catalogue.ch.KBOB2022.UBPDisposal | M1: vyzn.catalogue.ch.KBOB2022.RenewableEnergyTotal | N1: vyzn.catalogue.ch.KBOB2022.RenewableEnergyProduction | O1: vyzn.catalogue.ch.KBOB2022.RenewableEnergyDisposal | P1: vyzn.catalogue.ch.KBOB2022.GreyEnergyTotal | Q1: vyzn.catalogue.ch.KBOB2022.GreyEnergyProduction | R1: vyzn.catalogue.ch.KBOB2022.GreyEnergyDisposal | S1: vyzn.catalogue.ch.KBOB2022.GHGEmissionsTotal | T1: vyzn.catalogue.ch.KBOB2022.GHGEmissionsProduction | U1: vyzn.catalogue.ch.KBOB2022.GHGEmissionsDisposal | V1: vyzn.catalogue.ch.KBOB2022.LCARefUnit | W1: vyzn.catalogue.ch.KBOB2022.LCARefDimension | X1: vyzn.catalogue.ch.KBOB2022.BiogenicCarbon | Y1: KBOB REF | Z1: vyzn.catalogue.SourceENV | AA1: categoryPath | AB1: vyzn.catalogue.lifeCycle
A2: 00.001 Baugrubensicherung, Bohrpfahlwand, gespriesst (KBOB.2016) | B2: 00.001 Baugrubensicherung, Bohrpfahlwand, gespriesst (KBOB.2016) | F2: OTHER_RESOURCE | G2: OTHER_RESOURCE_CONSTRUCTION_MATERIAL_PREPARATION_WORK | J2: 1010000.000000 | K2: 877000.000000 | L2: 130000.000000 | M2: 110.000000 | N2: 101.000000 | O2: 9.570000 | P2: 2280.000000 | Q2: 2020.000000 | R2: 258.000000 | S2: 828.000000 | T2: 778.000000 | U2: 50.200000 | V2: m2 | W2: area | Y2: 00.001 | Z2: KBOB 2016 | AA2: Alle > RESSOURCEN > kbob.admin.ch > KBOB / ecobau / IPB 2009/1:2016 | AB2: 60
A3: 00.002 Baugrubensicherung, Bohrpfahlwand, unverankert (KBOB.2016) | B3: 00.002 Baugrubensicherung, Bohrpfahlwand, unverankert (KBOB.2016) | F3: OTHER_RESOURCE | G3: OTHER_RESOURCE_CONSTRUCTION_MATERIAL_PREPARATION_WORK | J3: 952000.000000 | K3: 822000.000000 | L3: 130000.000000 | M3: 94.300000 | N3: 84.800000 | O3: 9.570000 | P3: 2090.000000 | Q3: 1830.000000 | R3: 258.000000 | S3: 788.000000 | T3: 738.000000 | U3: 50.200000 | V3: m2 | W3: area | Y3: 00.002 | Z3: KBOB 2016 | AA3: Alle > RESSOURCEN > kbob.admin.ch > KBOB / ecobau / IPB 2009/1:2016 | AB3: 60
A4: 00.003 Baugrubensicherung, Bohrpfahlwand, verankert (KBOB.2016) | B4: 00.003 Baugrubensicherung, Bohrpfahlwand, verankert (KBOB.2016) | F4: OTHER_RESOURCE | G4: OTHER_RESOURCE_CONSTRUCTION_MATERIAL_PREPARATION_WORK | J4: 778000.000000 | K4: 692000.000000 | L4: 86200.000000 | M4: 82.800000 | N4: 76.400000 | O4: 6.320000 | P4: 1510.000000 | Q4: 1340.000000 | R4: 170.000000 | S4: 512.000000 | T4: 478.000000 | U4: 33.100000 | V4: m2 | W4: area | Y4: 00.003 | Z4: KBOB 2016 | AA4: Alle > RESSOURCEN > kbob.admin.ch > KBOB / ecobau / IPB 2009/1:2016 | AB4: 60
A5: 00.004 Baugrubensicherung, Nagelwand (KBOB.2016) | B5: 00.004 Baugrubensicherung, Nagelwand (KBOB.2016) | F5: OTHER_RESOURCE | G5: OTHER_RESOURCE_CONSTRUCTION_MATERIAL_PREPARATION_WORK | J5: 171000.000000 | K5: 152000.000000 | L5: 18900.000000 | M5: 17.900000 | N5: 16.600000 | O5: 1.390000 | P5: 324.000000 | Q5: 286.000000 | R5: 37.500000 | S5: 116.000000 | T5: 109.000000 | U5: 7.280000 | V5: m2 | W5: area | Y5: 00.004 | Z5: KBOB 2016 | AA5: Alle > RESSOURCEN > kbob.admin.ch > KBOB / ecobau / IPB 2009/1:2016 | AB5: 60
A6: 00.005 Baugrubensicherung, Rühlwand, auskragend (KBOB.2016) | B6: 00.005 Baugrubensicherung, Rühlwand, auskragend (KBOB.2016) | F6: OTHER_RESOURCE | G6: OTHER_RESOURCE_CONSTRUCTION_MATERIAL_PREPARATION_WORK | J6: 332000.000000 | K6: 302000.000000 | L6: 30100.000000 | M6: 108.000000 | N6: 106.000000 | O6: 2.200000 | P6: 934.000000 | Q6: 874.000000 | R6: 59.500000 | S6: 266.000000 | T6: 254.000000 | U6: 11.600000 | V6: m2 | W6: area | Y6: 00.005 | Z6: KBOB 2016 | AA6: Alle > RESSOURCEN > kbob.admin.ch > KBOB / ecobau / IPB 2009/1:2016 | AB6: 60
A7: 00.006 Baugrubensicherung, Rühlwand, gespriesst (KBOB.2016) | B7: 00.006 Baugrubensicherung, Rühlwand, gespriesst (KBOB.2016) | F7: OTHER_RESOURCE | G7: OTHER_RESOURCE_CONSTRUCTION_MATERIAL_PREPARATION_WORK | J7: 240000.000000 | K7: 222000.000000 | L7: 17800.000000 | M7: 46.700000 | N7: 45.400000 | O7: 1.310000 | P7: 677.000000 | Q7: 642.000000 | R7: 35.200000 | S7: 184.000000 | T7: 177.000000 | U7: 6.840000 | V7: m2 | W7: area | Y7: 00.006 | Z7: KBOB 2016 | AA7: Alle > RESSOURCEN > kbob.admin.ch > KBOB / ecobau / IPB 2009/1:2016 | AB7: 60
A8: 00.007 Baugrubensicherung, Rühlwand, verankert (KBOB.2016) | B8: 00.007 Baugrubensicherung, Rühlwand, verankert (KBOB.2016) | F8: OTHER_RESOURCE | G8: OTHER_RESOURCE_CONSTRUCTION_MATERIAL_PREPARATION_WORK | J8: 259000.000000 | K8: 238000.000000 | L8: 20600.000000 | M8: 43.900000 | N8: 42.400000 | O8: 1.510000 | P8: 681.000000 | Q8: 640.000000 | R8: 40.700000 | S8: 192.000000 | T8: 184.000000 | U8: 7.900000 | V8: m2 | W8: area | Y8: 00.007 | Z8: KBOB 2016 | AA8: Alle > RESSOURCEN > kbob.admin.ch > KBOB / ecobau / IPB 2009/1:2016 | AB8: 60
A9: 00.008 Baugrubensicherung, Schlitzwand, 400 mm (KBOB.2016) | B9: 00.008 Baugrubensicherung, Schlitzwand, 400 mm (KBOB.2016) | F9: OTHER_RESOURCE | G9: OTHER_RESOURCE_CONSTRUCTION_MATERIAL_PREPARATION_WORK | J9: 648000.000000 | K9: 583000.000000 | L9: 65500.000000 | M9: 73.300000 | N9: 68.600000 | O9: 4.760000 | P9: 1250.000000 | Q9: 1120.000000 | R9: 130.000000 | S9: 407.000000 | T9: 382.000000 | U9: 25.200000 | V9: m2 | W9: area | Y9: 00.008 | Z9: KBOB 2016 | AA9: Alle > RESSOURCEN > kbob.admin.ch > KBOB / ecobau / IPB 2009/1:2016 | AB9: 60
A10: 00.009 Baugrubensicherung, Schlitzwand, 800 mm (KBOB.2016) | B10: 00.009 Baugrubensicherung, Schlitzwand, 800 mm (KBOB.2016) | F10: OTHER_RESOURCE | G10: OTHER_RESOURCE_CONSTRUCTION_MATERIAL_PREPARATION_WORK | J10: 1230000.000000 | K10: 1100000.000000 | L10: 129000.000000 | M10: 136.000000 | N10: 126.000000 | O10: 9.430000 | P10: 2270.000000 | Q10: 2010.000000 | R10: 256.000000 | S10: 777.000000 | T10: 728.000000 | U10: 49.600000 | V10: m2 | W10: area | Y10: 00.009 | Z10: KBOB 2016 | AA10: Alle > RESSOURCEN > kbob.admin.ch > KBOB / ecobau / IPB 2009/1:2016 | AB10: 60
A11: 00.010 Baugrubensicherung, Spundwand, auskragend (KBOB.2016) | B11: 00.010 Baugrubensicherung, Spundwand, auskragend (KBOB.2016) | F11: OTHER_RESOURCE | G11: OTHER_RESOURCE_CONSTRUCTION_MATERIAL_PREPARATION_WORK | J11: 228000.000000 | K11: 228000.000000 | L11: 0.000000 | M11: 46.200000 | N11: 46.200000 | O11: 0.000000 | P11: 747.000000 | Q11: 747.000000 | R11: 0.000000 | S11: 163.000000 | T11: 163.000000 | U11: 0.000000 | V11: m2 | W11: area | Y11: 00.010 | Z11: KBOB 2016 | AA11: Alle > RESSOURCEN > kbob.admin.ch > KBOB / ecobau / IPB 2009/1:2016 | AB11: 60
A12: 00.011 Baugrubensicherung, Spundwand, gespriesst (KBOB.2016) | B12: 00.011 Baugrubensicherung, Spundwand, gespriesst (KBOB.2016) | F12: OTHER_RESOURCE | G12: OTHER_RESOURCE_CONSTRUCTION_MATERIAL_PREPARATION_WORK | J12: 129000.000000 | K12: 129000.000000 | L12: 0.000000 | M12: 25.300000 | N12: 25.300000 | O12: 0.000000 | P12: 421.000000 | Q12: 421.000000 | R12: 0.000000 | S12: 92.300000 | T12: 92.300000 | U12: 0.000000 | V12: m2 | W12: area | Y12: 00.011 | Z12: KBOB 2016 | AA12: Alle > RESSOURCEN > kbob.admin.ch > KBOB / ecobau / IPB 2009/1:2016 | AB12: 60
A13: 00.012 Baugrubensicherung, Spundwand, verankert (KBOB.2016) | B13: 00.012 Baugrubensicherung, Spundwand, verankert (KBOB.2016) | F13: OTHER_RESOURCE | G13: OTHER_RESOURCE_CONSTRUCTION_MATERIAL_PREPARATION_WORK | J13: 255000.000000 | K13: 255000.000000 | L13: 0.000000 | M13: 55.300000 | N13: 55.300000 | O13: 0.000000 | P13: 813.000000 | Q13: 813.000000 | R13: 0.000000 | S13: 181.000000 | T13: 181.000000 | U13: 0.000000 | V13: m2 | W13: area | Y13: 00.012 | Z13: KBOB 2016 | AA13: Alle > RESSOURCEN > kbob.admin.ch > KBOB / ecobau / IPB 2009/1:2016 | AB13: 60
... A25: 00.024 Wasserhaltung, Pumphöhe 10 m (KBOB.2016) | B25: 00.024 Wasserhaltung, Pumphöhe 10 m (KBOB.2016) | F25: OTHER_RESOURCE | G25: OTHER_RESOURCE_CONSTRUCTION_MATERIAL_PREPARATION_WORK | J25: 22.500000 | K25: 22.500000 | L25: 0.000000 | M25: 0.030900 | N25: 0.030900 | O25: 0.000000 | P25: 0.159000 | Q25: 0.159000 | R25: 0.000000 | S25: 0.006560 | T25: 0.006560 | U25: 0.000000 | V25: m3 | W25: volume | Y25: 00.024 | Z25: KBOB 2016 | AA25: Alle > RESSOURCEN > kbob.admin.ch > KBOB / ecobau / IPB 2009/1:2016 | AB25: 60

Sheet ConsolidatedBaumaterialien
A1: Name | B1: ProductKey | C1: Description | D1: Picture | E1: Product sections | F1: Type | G1: SubType | H1: hatchingPattern | I1: vyzn.catalogue.Density | J1: vyzn.catalogue.ch.KBOB2022.UBPTotal | K1: vyzn.catalogue.ch.KBOB2022.UBPProduction | L1: vyzn.catalogue.ch.KBOB2022.UBPDisposal | M1: vyzn.catalogue.ch.KBOB2022.RenewableEnergyTotal | N1: vyzn.catalogue.ch.KBOB2022.RenewableEnergyProduction | O1: vyzn.catalogue.ch.KBOB2022.RenewableEnergyDisposal | P1: vyzn.catalogue.ch.KBOB2022.GreyEnergyTotal | Q1: vyzn.catalogue.ch.KBOB2022.GreyEnergyProduction | R1: vyzn.catalogue.ch.KBOB2022.GreyEnergyDisposal | S1: vyzn.catalogue.ch.KBOB2022.GHGEmissionsTotal | T1: vyzn.catalogue.ch.KBOB2022.GHGEmissionsProduction | U1: vyzn.catalogue.ch.KBOB2022.GHGEmissionsDisposal | V1: vyzn.catalogue.ch.KBOB2022.LCARefUnit | W1: vyzn.catalogue.ch.KBOB2022.LCARefDimension | X1: vyzn.catalogue.ch.KBOB2022.BiogenicCarbon | Y1: KBOB REF | Z1: vyzn.catalogue.SourceENV | AA1: categoryPath | AB1: vyzn.catalogue.lifeCycle
A2: ='Baumaterialien Matériaux'!A11 & " " & 'Baumaterialien Matériaux'!B11 & " (KBOB.2016)" -> 00.001 Baugrubensicherung, Bohrpfahlwand, gespriesst (KBOB.2016) | B2: =A2 -> 00.001 Baugrubensicherung, Bohrpfahlwand, gespriesst (KBOB.2016) | F2: OTHER_RESOURCE | G2: =SWITCH(LEFT(A2,2), "00", "OTHER_RESOURCE_CONSTRUCTION_MATERIAL_PREPARATION_WORK", "") -> OTHER_RESOURCE_CONSTRUCTION_MATERIAL_PREPARATION_WORK | J2: ='Baumaterialien Matériaux'!G11 -> 1010000 | K2: ='Baumaterialien Matériaux'!H11 -> 877000 | L2: ='Baumaterialien Matériaux'!I11 -> 130000 | M2: ='Baumaterialien Matériaux'!M11 -> 110 | N2: ='Baumaterialien Matériaux'!N11 -> 101 | O2: ='Baumaterialien Matériaux'!O11 -> 9.57 | P2: ='Baumaterialien Matériaux'!P11 -> 2280 | Q2: ='Baumaterialien Matériaux'!Q11 -> 2020 | R2: ='Baumaterialien Matériaux'!R11 -> 258 | S2: ='Baumaterialien Matériaux'!S11 -> 828 | T2: ='Baumaterialien Matériaux'!T11 -> 778 | U2: ='Baumaterialien Matériaux'!U11 -> 50.2 | V2: ='Baumaterialien Matériaux'!F11 -> m2 | W2: =SWITCH('Baumaterialien Matériaux'!F11, "m", "probeLength", "m2", "area", "m3", "volume", "kg", "mass", "Stk.", "device") -> area | X2: ='Baumaterialien Matériaux'!AC11 | Y2: =LEFT(A2,6) -> 00.001 | Z2: KBOB 2016 | AA2: ="Alle > " & SWITCH(F2, "COMPONENT","BAUTEILE", "OTHER_RESOURCE", "RESSOURCEN", "BUILDING_TECHNOLOGY", "GEBÄUDETECHNIK", "MATERIAL", "MATERIALIEN") & " > kbob.admin.ch > KBOB / ecobau / IPB 2009/1:2016" -> Alle > RESSOURCEN > kbob.admin.ch > KBOB / ecobau / IPB 2009/1:2016 | AB2: 60
A3: ='Baumaterialien Matériaux'!A12 & " " & 'Baumaterialien Matériaux'!B12 & " (KBOB.2016)" -> 00.002 Baugrubensicherung, Bohrpfahlwand, unverankert (KBOB.2016) | B3: =A3 -> 00.002 Baugrubensicherung, Bohrpfahlwand, unverankert (KBOB.2016) | F3: OTHER_RESOURCE | G3: =SWITCH(LEFT(A3,2), "00", "OTHER_RESOURCE_CONSTRUCTION_MATERIAL_PREPARATION_WORK", "") -> OTHER_RESOURCE_CONSTRUCTION_MATERIAL_PREPARATION_WORK | J3: ='Baumaterialien Matériaux'!G12 -> 952000 | K3: ='Baumaterialien Matériaux'!H12 -> 822000 | L3: ='Baumaterialien Matériaux'!I12 -> 130000 | M3: ='Baumaterialien Matériaux'!M12 -> 94.3 | N3: ='Baumaterialien Matériaux'!N12 -> 84.8 | O3: ='Baumaterialien Matériaux'!O12 -> 9.57 | P3: ='Baumaterialien Matériaux'!P12 -> 2090 | Q3: ='Baumaterialien Matériaux'!Q12 -> 1830 | R3: ='Baumaterialien Matériaux'!R12 -> 258 | S3: ='Baumaterialien Matériaux'!S12 -> 788 | T3: ='Baumaterialien Matériaux'!T12 -> 738 | U3: ='Baumaterialien Matériaux'!U12 -> 50.2 | V3: ='Baumaterialien Matériaux'!F12 -> m2 | W3: =SWITCH('Baumaterialien Matériaux'!F12, "m", "probeLength", "m2", "area", "m3", "volume", "kg", "mass", "Stk.", "device") -> area | X3: ='Baumaterialien Matériaux'!AC12 | Y3: =LEFT(A3,6) -> 00.002 | Z3: KBOB 2016 | AA3: ="Alle > " & SWITCH(F3, "COMPONENT","BAUTEILE", "OTHER_RESOURCE", "RESSOURCEN", "BUILDING_TECHNOLOGY", "GEBÄUDETECHNIK", "MATERIAL", "MATERIALIEN") & " > kbob.admin.ch > KBOB / ecobau / IPB 2009/1:2016" -> Alle > RESSOURCEN > kbob.admin.ch > KBOB / ecobau / IPB 2009/1:2016 | AB3: 60
A4: ='Baumaterialien Matériaux'!A13 & " " & 'Baumaterialien Matériaux'!B13 & " (KBOB.2016)" -> 00.003 Baugrubensicherung, Bohrpfahlwand, verankert (KBOB.2016) | B4: =A4 -> 00.003 Baugrubensicherung, Bohrpfahlwand, verankert (KBOB.2016) | F4: OTHER_RESOURCE | G4: =SWITCH(LEFT(A4,2), "00", "OTHER_RESOURCE_CONSTRUCTION_MATERIAL_PREPARATION_WORK", "") -> OTHER_RESOURCE_CONSTRUCTION_MATERIAL_PREPARATION_WORK | J4: ='Baumaterialien Matériaux'!G13 -> 778000 | K4: ='Baumaterialien Matériaux'!H13 -> 692000 | L4: ='Baumaterialien Matériaux'!I13 -> 86200 | M4: ='Baumaterialien Matériaux'!M13 -> 82.8 | N4: ='Baumaterialien Matériaux'!N13 -> 76.4 | O4: ='Baumaterialien Matériaux'!O13 -> 6.32 | P4: ='Baumaterialien Matériaux'!P13 -> 1510 | Q4: ='Baumaterialien Matériaux'!Q13 -> 1340 | R4: ='Baumaterialien Matériaux'!R13 -> 170 | S4: ='Baumaterialien Matériaux'!S13 -> 512 | T4: ='Baumaterialien Matériaux'!T13 -> 478 | U4: ='Baumaterialien Matériaux'!U13 -> 33.1 | V4: ='Baumaterialien Matériaux'!F13 -> m2 | W4: =SWITCH('Baumaterialien Matériaux'!F13, "m", "probeLength", "m2", "area", "m3", "volume", "kg", "mass", "Stk.", "device") -> area | X4: ='Baumaterialien Matériaux'!AC13 | Y4: =LEFT(A4,6) -> 00.003 | Z4: KBOB 2016 | AA4: ="Alle > " & SWITCH(F4, "COMPONENT","BAUTEILE", "OTHER_RESOURCE", "RESSOURCEN", "BUILDING_TECHNOLOGY", "GEBÄUDETECHNIK", "MATERIAL", "MATERIALIEN") & " > kbob.admin.ch > KBOB / ecobau / IPB 2009/1:2016" -> Alle > RESSOURCEN > kbob.admin.ch > KBOB / ecobau / IPB 2009/1:2016 | AB4: 60
A5: ='Baumaterialien Matériaux'!A14 & " " & 'Baumaterialien Matériaux'!B14 & " (KBOB.2016)" -> 00.004 Baugrubensicherung, Nagelwand (KBOB.2016) | B5: =A5 -> 00.004 Baugrubensicherung, Nagelwand (KBOB.2016) | F5: OTHER_RESOURCE | G5: =SWITCH(LEFT(A5,2), "00", "OTHER_RESOURCE_CONSTRUCTION_MATERIAL_PREPARATION_WORK", "") -> OTHER_RESOURCE_CONSTRUCTION_MATERIAL_PREPARATION_WORK | J5: ='Baumaterialien Matériaux'!G14 -> 171000 | K5: ='Baumaterialien Matériaux'!H14 -> 152000 | L5: ='Baumaterialien Matériaux'!I14 -> 18900 | M5: ='Baumaterialien Matériaux'!M14 -> 17.9 | N5: ='Baumaterialien Matériaux'!N14 -> 16.6 | O5: ='Baumaterialien Matériaux'!O14 -> 1.39 | P5: ='Baumaterialien Matériaux'!P14 -> 324 | Q5: ='Baumaterialien Matériaux'!Q14 -> 286 | R5: ='Baumaterialien Matériaux'!R14 -> 37.5 | S5: ='Baumaterialien Matériaux'!S14 -> 116 | T5: ='Baumaterialien Matériaux'!T14 -> 109 | U5: ='Baumaterialien Matériaux'!U14 -> 7.28 | V5: ='Baumaterialien Matériaux'!F14 -> m2 | W5: =SWITCH('Baumaterialien Matériaux'!F14, "m", "probeLength", "m2", "area", "m3", "volume", "kg", "mass", "Stk.", "device") -> area | X5: ='Baumaterialien Matériaux'!AC14 | Y5: =LEFT(A5,6) -> 00.004 | Z5: KBOB 2016 | AA5: ="Alle > " & SWITCH(F5, "COMPONENT","BAUTEILE", "OTHER_RESOURCE", "RESSOURCEN", "BUILDING_TECHNOLOGY", "GEBÄUDETECHNIK", "MATERIAL", "MATERIALIEN") & " > kbob.admin.ch > KBOB / ecobau / IPB 2009/1:2016" -> Alle > RESSOURCEN > kbob.admin.ch > KBOB / ecobau / IPB 2009/1:2016 | AB5: 60
A6: ='Baumaterialien Matériaux'!A15 & " " & 'Baumaterialien Matériaux'!B15 & " (KBOB.2016)" -> 00.005 Baugrubensicherung, Rühlwand, auskragend (KBOB.2016) | B6: =A6 -> 00.005 Baugrubensicherung, Rühlwand, auskragend (KBOB.2016) | F6: OTHER_RESOURCE | G6: =SWITCH(LEFT(A6,2), "00", "OTHER_RESOURCE_CONSTRUCTION_MATERIAL_PREPARATION_WORK", "") -> OTHER_RESOURCE_CONSTRUCTION_MATERIAL_PREPARATION_WORK | J6: ='Baumaterialien Matériaux'!G15 -> 332000 | K6: ='Baumaterialien Matériaux'!H15 -> 302000 | L6: ='Baumaterialien Matériaux'!I15 -> 30100 | M6: ='Baumaterialien Matériaux'!M15 -> 108 | N6: ='Baumaterialien Matériaux'!N15 -> 106 | O6: ='Baumaterialien Matériaux'!O15 -> 2.2 | P6: ='Baumaterialien Matériaux'!P15 -> 934 | Q6: ='Baumaterialien Matériaux'!Q15 -> 874 | R6: ='Baumaterialien Matériaux'!R15 -> 59.5 | S6: ='Baumaterialien Matériaux'!S15 -> 266 | T6: ='Baumaterialien Matériaux'!T15 -> 254 | U6: ='Baumaterialien Matériaux'!U15 -> 11.6 | V6: ='Baumaterialien Matériaux'!F15 -> m2 | W6: =SWITCH('Baumaterialien Matériaux'!F15, "m", "probeLength", "m2", "area", "m3", "volume", "kg", "mass", "Stk.", "device") -> area | X6: ='Baumaterialien Matériaux'!AC15 | Y6: =LEFT(A6,6) -> 00.005 | Z6: KBOB 2016 | AA6: ="Alle > " & SWITCH(F6, "COMPONENT","BAUTEILE", "OTHER_RESOURCE", "RESSOURCEN", "BUILDING_TECHNOLOGY", "GEBÄUDETECHNIK", "MATERIAL", "MATERIALIEN") & " > kbob.admin.ch > KBOB / ecobau / IPB 2009/1:2016" -> Alle > RESSOURCEN > kbob.admin.ch > KBOB / ecobau / IPB 2009/1:2016 | AB6: 60
A7: ='Baumaterialien Matériaux'!A16 & " " & 'Baumaterialien Matériaux'!B16 & " (KBOB.2016)" -> 00.006 Baugrubensicherung, Rühlwand, gespriesst (KBOB.2016) | B7: =A7 -> 00.006 Baugrubensicherung, Rühlwand, gespriesst (KBOB.2016) | F7: OTHER_RESOURCE | G7: =SWITCH(LEFT(A7,2), "00", "OTHER_RESOURCE_CONSTRUCTION_MATERIAL_PREPARATION_WORK", "") -> OTHER_RESOURCE_CONSTRUCTION_MATERIAL_PREPARATION_WORK | J7: ='Baumaterialien Matériaux'!G16 -> 240000 | K7: ='Baumaterialien Matériaux'!H16 -> 222000 | L7: ='Baumaterialien Matériaux'!I16 -> 17800 | M7: ='Baumaterialien Matériaux'!M16 -> 46.7 | N7: ='Baumaterialien Matériaux'!N16 -> 45.4 | O7: ='Baumaterialien Matériaux'!O16 -> 1.31 | P7: ='Baumaterialien Matériaux'!P16 -> 677 | Q7: ='Baumaterialien Matériaux'!Q16 -> 642 | R7: ='Baumaterialien Matériaux'!R16 -> 35.2 | S7: ='Baumaterialien Matériaux'!S16 -> 184 | T7: ='Baumaterialien Matériaux'!T16 -> 177 | U7: ='Baumaterialien Matériaux'!U16 -> 6.84 | V7: ='Baumaterialien Matériaux'!F16 -> m2 | W7: =SWITCH('Baumaterialien Matériaux'!F16, "m", "probeLength", "m2", "area", "m3", "volume", "kg", "mass", "Stk.", "device") -> area | X7: ='Baumaterialien Matériaux'!AC16 | Y7: =LEFT(A7,6) -> 00.006 | Z7: KBOB 2016 | AA7: ="Alle > " & SWITCH(F7, "COMPONENT","BAUTEILE", "OTHER_RESOURCE", "RESSOURCEN", "BUILDING_TECHNOLOGY", "GEBÄUDETECHNIK", "MATERIAL", "MATERIALIEN") & " > kbob.admin.ch > KBOB / ecobau / IPB 2009/1:2016" -> Alle > RESSOURCEN > kbob.admin.ch > KBOB / ecobau / IPB 2009/1:2016 | AB7: 60
A8: ='Baumaterialien Matériaux'!A17 & " " & 'Baumaterialien Matériaux'!B17 & " (KBOB.2016)" -> 00.007 Baugrubensicherung, Rühlwand, verankert (KBOB.2016) | B8: =A8 -> 00.007 Baugrubensicherung, Rühlwand, verankert (KBOB.2016) | F8: OTHER_RESOURCE | G8: =SWITCH(LEFT(A8,2), "00", "OTHER_RESOURCE_CONSTRUCTION_MATERIAL_PREPARATION_WORK", "") -> OTHER_RESOURCE_CONSTRUCTION_MATERIAL_PREPARATION_WORK | J8: ='Baumaterialien Matériaux'!G17 -> 259000 | K8: ='Baumaterialien Matériaux'!H17 -> 238000 | L8: ='Baumaterialien Matériaux'!I17 -> 20600 | M8: ='Baumaterialien Matériaux'!M17 -> 43.9 | N8: ='Baumaterialien Matériaux'!N17 -> 42.4 | O8: ='Baumaterialien Matériaux'!O17 -> 1.51 | P8: ='Baumaterialien Matériaux'!P17 -> 681 | Q8: ='Baumaterialien Matériaux'!Q17 -> 640 | R8: ='Baumaterialien Matériaux'!R17 -> 40.7 | S8: ='Baumaterialien Matériaux'!S17 -> 192 | T8: ='Baumaterialien Matériaux'!T17 -> 184 | U8: ='Baumaterialien Matériaux'!U17 -> 7.9 | V8: ='Baumaterialien Matériaux'!F17 -> m2 | W8: =SWITCH('Baumaterialien Matériaux'!F17, "m", "probeLength", "m2", "area", "m3", "volume", "kg", "mass", "Stk.", "device") -> area | X8: ='Baumaterialien Matériaux'!AC17 | Y8: =LEFT(A8,6) -> 00.007 | Z8: KBOB 2016 | AA8: ="Alle > " & SWITCH(F8, "COMPONENT","BAUTEILE", "OTHER_RESOURCE", "RESSOURCEN", "BUILDING_TECHNOLOGY", "GEBÄUDETECHNIK", "MATERIAL", "MATERIALIEN") & " > kbob.admin.ch > KBOB / ecobau / IPB 2009/1:2016" -> Alle > RESSOURCEN > kbob.admin.ch > KBOB / ecobau / IPB 2009/1:2016 | AB8: 60
A9: ='Baumaterialien Matériaux'!A18 & " " & 'Baumaterialien Matériaux'!B18 & " (KBOB.2016)" -> 00.008 Baugrubensicherung, Schlitzwand, 400 mm (KBOB.2016) | B9: =A9 -> 00.008 Baugrubensicherung, Schlitzwand, 400 mm (KBOB.2016) | F9: OTHER_RESOURCE | G9: =SWITCH(LEFT(A9,2), "00", "OTHER_RESOURCE_CONSTRUCTION_MATERIAL_PREPARATION_WORK", "") -> OTHER_RESOURCE_CONSTRUCTION_MATERIAL_PREPARATION_WORK | J9: ='Baumaterialien Matériaux'!G18 -> 648000 | K9: ='Baumaterialien Matériaux'!H18 -> 583000 | L9: ='Baumaterialien Matériaux'!I18 -> 65500 | M9: ='Baumaterialien Matériaux'!M18 -> 73.3 | N9: ='Baumaterialien Matériaux'!N18 -> 68.6 | O9: ='Baumaterialien Matériaux'!O18 -> 4.76 | P9: ='Baumaterialien Matériaux'!P18 -> 1250 | Q9: ='Baumaterialien Matériaux'!Q18 -> 1120 | R9: ='Baumaterialien Matériaux'!R18 -> 130 | S9: ='Baumaterialien Matériaux'!S18 -> 407 | T9: ='Baumaterialien Matériaux'!T18 -> 382 | U9: ='Baumaterialien Matériaux'!U18 -> 25.2 | V9: ='Baumaterialien Matériaux'!F18 -> m2 | W9: =SWITCH('Baumaterialien Matériaux'!F18, "m", "probeLength", "m2", "area", "m3", "volume", "kg", "mass", "Stk.", "device") -> area | X9: ='Baumaterialien Matériaux'!AC18 | Y9: =LEFT(A9,6) -> 00.008 | Z9: KBOB 2016 | AA9: ="Alle > " & SWITCH(F9, "COMPONENT","BAUTEILE", "OTHER_RESOURCE", "RESSOURCEN", "BUILDING_TECHNOLOGY", "GEBÄUDETECHNIK", "MATERIAL", "MATERIALIEN") & " > kbob.admin.ch > KBOB / ecobau / IPB 2009/1:2016" -> Alle > RESSOURCEN > kbob.admin.ch > KBOB / ecobau / IPB 2009/1:2016 | AB9: 60
A10: ='Baumaterialien Matériaux'!A19 & " " & 'Baumaterialien Matériaux'!B19 & " (KBOB.2016)" -> 00.009 Baugrubensicherung, Schlitzwand, 800 mm (KBOB.2016) | B10: =A10 -> 00.009 Baugrubensicherung, Schlitzwand, 800 mm (KBOB.2016) | F10: OTHER_RESOURCE | G10: =SWITCH(LEFT(A10,2), "00", "OTHER_RESOURCE_CONSTRUCTION_MATERIAL_PREPARATION_WORK", "") -> OTHER_RESOURCE_CONSTRUCTION_MATERIAL_PREPARATION_WORK | J10: ='Baumaterialien Matériaux'!G19 -> 1230000 | K10: ='Baumaterialien Matériaux'!H19 -> 1100000 | L10: ='Baumaterialien Matériaux'!I19 -> 129000 | M10: ='Baumaterialien Matériaux'!M19 -> 136 | N10: ='Baumaterialien Matériaux'!N19 -> 126 | O10: ='Baumaterialien Matériaux'!O19 -> 9.43 | P10: ='Baumaterialien Matériaux'!P19 -> 2270 | Q10: ='Baumaterialien Matériaux'!Q19 -> 2010 | R10: ='Baumaterialien Matériaux'!R19 -> 256 | S10: ='Baumaterialien Matériaux'!S19 -> 777 | T10: ='Baumaterialien Matériaux'!T19 -> 728 | U10: ='Baumaterialien Matériaux'!U19 -> 49.6 | V10: ='Baumaterialien Matériaux'!F19 -> m2 | W10: =SWITCH('Baumaterialien Matériaux'!F19, "m", "probeLength", "m2", "area", "m3", "volume", "kg", "mass", "Stk.", "device") -> area | X10: ='Baumaterialien Matériaux'!AC19 | Y10: =LEFT(A10,6) -> 00.009 | Z10: KBOB 2016 | AA10: ="Alle > " & SWITCH(F10, "COMPONENT","BAUTEILE", "OTHER_RESOURCE", "RESSOURCEN", "BUILDING_TECHNOLOGY", "GEBÄUDETECHNIK", "MATERIAL", "MATERIALIEN") & " > kbob.admin.ch > KBOB / ecobau / IPB 2009/1:2016" -> Alle > RESSOURCEN > kbob.admin.ch > KBOB / ecobau / IPB 2009/1:2016 | AB10: 60
A11: ='Baumaterialien Matériaux'!A20 & " " & 'Baumaterialien Matériaux'!B20 & " (KBOB.2016)" -> 00.010 Baugrubensicherung, Spundwand, auskragend (KBOB.2016) | B11: =A11 -> 00.010 Baugrubensicherung, Spundwand, auskragend (KBOB.2016) | F11: OTHER_RESOURCE | G11: =SWITCH(LEFT(A11,2), "00", "OTHER_RESOURCE_CONSTRUCTION_MATERIAL_PREPARATION_WORK", "") -> OTHER_RESOURCE_CONSTRUCTION_MATERIAL_PREPARATION_WORK | J11: ='Baumaterialien Matériaux'!G20 -> 228000 | K11: ='Baumaterialien Matériaux'!H20 -> 228000 | L11: ='Baumaterialien Matériaux'!I20 -> 0 | M11: ='Baumaterialien Matériaux'!M20 -> 46.2 | N11: ='Baumaterialien Matériaux'!N20 -> 46.2 | O11: ='Baumaterialien Matériaux'!O20 -> 0 | P11: ='Baumaterialien Matériaux'!P20 -> 747 | Q11: ='Baumaterialien Matériaux'!Q20 -> 747 | R11: ='Baumaterialien Matériaux'!R20 -> 0 | S11: ='Baumaterialien Matériaux'!S20 -> 163 | T11: ='Baumaterialien Matériaux'!T20 -> 163 | U11: ='Baumaterialien Matériaux'!U20 -> 0 | V11: ='Baumaterialien Matériaux'!F20 -> m2 | W11: =SWITCH('Baumaterialien Matériaux'!F20, "m", "probeLength", "m2", "area", "m3", "volume", "kg", "mass", "Stk.", "device") -> area | X11: ='Baumaterialien Matériaux'!AC20 | Y11: =LEFT(A11,6) -> 00.010 | Z11: KBOB 2016 | AA11: ="Alle > " & SWITCH(F11, "COMPONENT","BAUTEILE", "OTHER_RESOURCE", "RESSOURCEN", "BUILDING_TECHNOLOGY", "GEBÄUDETECHNIK", "MATERIAL", "MATERIALIEN") & " > kbob.admin.ch > KBOB / ecobau / IPB 2009/1:2016" -> Alle > RESSOURCEN > kbob.admin.ch > KBOB / ecobau / IPB 2009/1:2016 | AB11: 60
A12: ='Baumaterialien Matériaux'!A21 & " " & 'Baumaterialien Matériaux'!B21 & " (KBOB.2016)" -> 00.011 Baugrubensicherung, Spundwand, gespriesst (KBOB.2016) | B12: =A12 -> 00.011 Baugrubensicherung, Spundwand, gespriesst (KBOB.2016) | F12: OTHER_RESOURCE | G12: =SWITCH(LEFT(A12,2), "00", "OTHER_RESOURCE_CONSTRUCTION_MATERIAL_PREPARATION_WORK", "") -> OTHER_RESOURCE_CONSTRUCTION_MATERIAL_PREPARATION_WORK | J12: ='Baumaterialien Matériaux'!G21 -> 129000 | K12: ='Baumaterialien Matériaux'!H21 -> 129000 | L12: ='Baumaterialien Matériaux'!I21 -> 0 | M12: ='Baumaterialien Matériaux'!M21 -> 25.3 | N12: ='Baumaterialien Matériaux'!N21 -> 25.3 | O12: ='Baumaterialien Matériaux'!O21 -> 0 | P12: ='Baumaterialien Matériaux'!P21 -> 421 | Q12: ='Baumaterialien Matériaux'!Q21 -> 421 | R12: ='Baumaterialien Matériaux'!R21 -> 0 | S12: ='Baumaterialien Matériaux'!S21 -> 92.3 | T12: ='Baumaterialien Matériaux'!T21 -> 92.3 | U12: ='Baumaterialien Matériaux'!U21 -> 0 | V12: ='Baumaterialien Matériaux'!F21 -> m2 | W12: =SWITCH('Baumaterialien Matériaux'!F21, "m", "probeLength", "m2", "area", "m3", "volume", "kg", "mass", "Stk.", "device") -> area | X12: ='Baumaterialien Matériaux'!AC21 | Y12: =LEFT(A12,6) -> 00.011 | Z12: KBOB 2016 | AA12: ="Alle > " & SWITCH(F12, "COMPONENT","BAUTEILE", "OTHER_RESOURCE", "RESSOURCEN", "BUILDING_TECHNOLOGY", "GEBÄUDETECHNIK", "MATERIAL", "MATERIALIEN") & " > kbob.admin.ch > KBOB / ecobau / IPB 2009/1:2016" -> Alle > RESSOURCEN > kbob.admin.ch > KBOB / ecobau / IPB 2009/1:2016 | AB12: 60
A13: ='Baumaterialien Matériaux'!A22 & " " & 'Baumaterialien Matériaux'!B22 & " (KBOB.2016)" -> 00.012 Baugrubensicherung, Spundwand, verankert (KBOB.2016) | B13: =A13 -> 00.012 Baugrubensicherung, Spundwand, verankert (KBOB.2016) | F13: OTHER_RESOURCE | G13: =SWITCH(LEFT(A13,2), "00", "OTHER_RESOURCE_CONSTRUCTION_MATERIAL_PREPARATION_WORK", "") -> OTHER_RESOURCE_CONSTRUCTION_MATERIAL_PREPARATION_WORK | J13: ='Baumaterialien Matériaux'!G22 -> 255000 | K13: ='Baumaterialien Matériaux'!H22 -> 255000 | L13: ='Baumaterialien Matériaux'!I22 -> 0 | M13: ='Baumaterialien Matériaux'!M22 -> 55.3 | N13: ='Baumaterialien Matériaux'!N22 -> 55.3 | O13: ='Baumaterialien Matériaux'!O22 -> 0 | P13: ='Baumaterialien Matériaux'!P22 -> 813 | Q13: ='Baumaterialien Matériaux'!Q22 -> 813 | R13: ='Baumaterialien Matériaux'!R22 -> 0 | S13: ='Baumaterialien Matériaux'!S22 -> 181 | T13: ='Baumaterialien Matériaux'!T22 -> 181 | U13: ='Baumaterialien Matériaux'!U22 -> 0 | V13: ='Baumaterialien Matériaux'!F22 -> m2 | W13: =SWITCH('Baumaterialien Matériaux'!F22, "m", "probeLength", "m2", "area", "m3", "volume", "kg", "mass", "Stk.", "device") -> area | X13: ='Baumaterialien Matériaux'!AC22 | Y13: =LEFT(A13,6) -> 00.012 | Z13: KBOB 2016 | AA13: ="Alle > " & SWITCH(F13, "COMPONENT","BAUTEILE", "OTHER_RESOURCE", "RESSOURCEN", "BUILDING_TECHNOLOGY", "GEBÄUDETECHNIK", "MATERIAL", "MATERIALIEN") & " > kbob.admin.ch > KBOB / ecobau / IPB 2009/1:2016" -> Alle > RESSOURCEN > kbob.admin.ch > KBOB / ecobau / IPB 2009/1:2016 | AB13: 60
... A25: ='Baumaterialien Matériaux'!A34 & " " & 'Baumaterialien Matériaux'!B34 & " (KBOB.2016)" -> 00.024 Wasserhaltung, Pumphöhe 10 m (KBOB.2016) | B25: =A25 -> 00.024 Wasserhaltung, Pumphöhe 10 m (KBOB.2016) | F25: OTHER_RESOURCE | G25: =SWITCH(LEFT(A25,2), "00", "OTHER_RESOURCE_CONSTRUCTION_MATERIAL_PREPARATION_WORK", "") -> OTHER_RESOURCE_CONSTRUCTION_MATERIAL_PREPARATION_WORK | J25: ='Baumaterialien Matériaux'!G34 -> 22.5 | K25: ='Baumaterialien Matériaux'!H34 -> 22.5 | L25: ='Baumaterialien Matériaux'!I34 -> 0 | M25: ='Baumaterialien Matériaux'!M34 -> 0.0309 | N25: ='Baumaterialien Matériaux'!N34 -> 0.0309 | O25: ='Baumaterialien Matériaux'!O34 -> 0 | P25: ='Baumaterialien Matériaux'!P34 -> 0.159 | Q25: ='Baumaterialien Matériaux'!Q34 -> 0.159 | R25: ='Baumaterialien Matériaux'!R34 -> 0 | S25: ='Baumaterialien Matériaux'!S34 -> 0.00656 | T25: ='Baumaterialien Matériaux'!T34 -> 0.00656 | U25: ='Baumaterialien Matériaux'!U34 -> 0 | V25: ='Baumaterialien Matériaux'!F34 -> m3 | W25: =SWITCH('Baumaterialien Matériaux'!F34, "m", "probeLength", "m2", "area", "m3", "volume", "kg", "mass", "Stk.", "device") -> volume | X25: ='Baumaterialien Matériaux'!AC34 | Y25: =LEFT(A25,6) -> 00.024 | Z25: KBOB 2016 | AA25: ="Alle > " & SWITCH(F25, "COMPONENT","BAUTEILE", "OTHER_RESOURCE", "RESSOURCEN", "BUILDING_TECHNOLOGY", "GEBÄUDETECHNIK", "MATERIAL", "MATERIALIEN") & " > kbob.admin.ch > KBOB / ecobau / IPB 2009/1:2016" -> Alle > RESSOURCEN > kbob.admin.ch > KBOB / ecobau / IPB 2009/1:2016 | AB25: 60

Sheet Baumaterialien Matériaux
B1: Ökobilanzdaten im Baubereich | M1: KBOB / eco-bau / IPB 2009/1:2016 | V1: Données écobilans dans la construction
H3: Total | I3: Total | K3: Total | L3: Total | N3: Total, renewable | O3: Total, renewable | Q3: Total, non-renewable | R3: Total, non-renewable | T3: IPCC GWP 100a | U3: IPCC GWP 100a
A4: ID-Nummer | B4: BAUMATERIALIEN [Bibliographie treeze, version 2.2:2016] | C4: ID-Nummer Entsorgung | D4: Entsorgung | E4: Rohdichte/ Flächen-masse | F4: Bezug Référence | G4: UBP'13 | J4: Primärenergie Energie primaire | S4: Treibhaus- gasemissionen | V4: MATÉRIAUX [Bibliographie treeze, version 2.2:2016]
A5: No d'identi-fication | C5: No d'identification Déchets | G5: UBP | J5: gesamt | M5: erneuerbar | P5: nicht erneuerbar (Graue Energie) | S5: Emissions de gaz
E6: Masse volumique/ surface | J6: globale | M6: renouvelable | P6: non renouvelable (énergie grise) | S6: à effet de serre
B7: Hinweis: Anzeigen der herstellerspezifischen und herstellerregionenspezifischen Daten durch Anklicken der '+' am linken Rand. | G7: Total | H7: Herstellung | I7: Entsorgung | J7: Total | K7: Herstellung | L7: Entsorgung | M7: Total | N7: Herstellung | O7: Entsorgung | P7: Total | Q7: Herstellung | R7: Entsorgung | S7: Total | T7: Herstellung | U7: Entsorgung | V7: Remarque: Affichage des données spécifiques aux fabricants et aux régions de production en cliquant sur les '+' sur le bord gauche.
G8: Total | H8: Fabrication | I8: Elimination | J8: Total | K8: Fabrication | L8: Elimination | M8: Total | N8: Fabrication | O8: Elimination | P8: Total | Q8: Fabrication | R8: Elimination | S8: Total | T8: Fabrication | U8: Elimination
G9: UBP | H9: UBP | I9: UBP | J9: kWh oil-eq | K9: kWh oil-eq | L9: kWh oil-eq | M9: kWh oil-eq | N9: kWh oil-eq | O9: kWh oil-eq | P9: kWh oil-eq | Q9: kWh oil-eq | R9: kWh oil-eq | S9: kg CO2-eq | T9: kg CO2-eq | U9: kg CO2-eq
A10: 0 | B10: Vorbereitungsarbeiten | E10: - | V10: Travails de préparation
A11: 00.001 | B11: Baugrubensicherung, Bohrpfahlwand, gespriesst | C11: 91.074 | D11: Entsorgung, Baugrubensicherung, Bohrpfahlwand, gespriesst | E11: - | F11: m2 | G11: 1010000 | H11: 877000 | I11: 130000 | J11: 2390 | K11: 2120 | L11: 268 | M11: 110 | N11: 101 | O11: 9.57 | P11: 2280 | Q11: 2020 | R11: 258 | S11: 828 | T11: 778 | U11: 50.2 | V11: Blindage de fouille, paroi parisienne, étayé
A12: 00.002 | B12: Baugrubensicherung, Bohrpfahlwand, unverankert | C12: 91.075 | D12: Entsorgung, Baugrubensicherung, Bohrpfahlwand, unverankert | E12: - | F12: m2 | G12: 952000 | H12: 822000 | I12: 130000 | J12: 2180 | K12: 1910 | L12: 268 | M12: 94.3 | N12: 84.8 | O12: 9.57 | P12: 2090 | Q12: 1830 | R12: 258 | S12: 788 | T12: 738 | U12: 50.2 | V12: Blindage de fouille, paroi parisienne, flottant
A13: 00.003 | B13: Baugrubensicherung, Bohrpfahlwand, verankert | C13: 91.076 | D13: Entsorgung, Baugrubensicherung, Bohrpfahlwand, verankert | E13: - | F13: m2 | G13: 778000 | H13: 692000 | I13: 86200 | J13: 1590 | K13: 1410 | L13: 177 | M13: 82.8 | N13: 76.4 | O13: 6.32 | P13: 1510 | Q13: 1340 | R13: 170 | S13: 512 | T13: 478 | U13: 33.1 | V13: Blindage de fouille, paroi parisienne, fixe
A14: 00.004 | B14: Baugrubensicherung, Nagelwand | C14: 91.077 | D14: Entsorgung, Baugrubensicherung, Nagelwand | E14: - | F14: m2 | G14: 171000 | H14: 152000 | I14: 18900 | J14: 342 | K14: 303 | L14: 38.8 | M14: 17.9 | N14: 16.6 | O14: 1.39 | P14: 324 | Q14: 286 | R14: 37.5 | S14: 116 | T14: 109 | U14: 7.28 | V14: Blindage de fouille, paroi clouée
A15: 00.005 | B15: Baugrubensicherung, Rühlwand, auskragend | C15: 91.078 | D15: Entsorgung, Baugrubensicherung, Rühlwand, auskragend | E15: - | F15: m2 | G15: 332000 | H15: 302000 | I15: 30100 | J15: 1040 | K15: 980 | L15: 61.7 | M15: 108 | N15: 106 | O15: 2.2 | P15: 934 | Q15: 874 | R15: 59.5 | S15: 266 | T15: 254 | U15: 11.6 | V15: Blindage de fouille, paroi berlinoise, en porte-à-faux
A16: 00.006 | B16: Baugrubensicherung, Rühlwand, gespriesst | C16: 91.079 | D16: Entsorgung, Baugrubensicherung, Rühlwand, gespriesst | E16: - | F16: m2 | G16: 240000 | H16: 222000 | I16: 17800 | J16: 724 | K16: 687 | L16: 36.5 | M16: 46.7 | N16: 45.4 | O16: 1.31 | P16: 677 | Q16: 642 | R16: 35.2 | S16: 184 | T16: 177 | U16: 6.84 | V16: Blindage de fouille, paroi berlinoise, étayé
A17: 00.007 | B17: Baugrubensicherung, Rühlwand, verankert | C17: 91.080 | D17: Entsorgung, Baugrubensicherung, Rühlwand, verankert | E17: - | F17: m2 | G17: 259000 | H17: 238000 | I17: 20600 | J17: 725 | K17: 683 | L17: 42.2 | M17: 43.9 | N17: 42.4 | O17: 1.51 | P17: 681 | Q17: 640 | R17: 40.7 | S17: 192 | T17: 184 | U17: 7.9 | V17: Blindage de fouille, paroi berlinoise, fixe
A18: 00.008 | B18: Baugrubensicherung, Schlitzwand, 400 mm | C18: 91.081 | D18: Entsorgung, Baugrubensicherung, Schlitzwand, 400mm | E18: - | F18: m2 | G18: 648000 | H18: 583000 | I18: 65500 | J18: 1320 | K18: 1190 | L18: 135 | M18: 73.3 | N18: 68.6 | O18: 4.76 | P18: 1250 | Q18: 1120 | R18: 130 | S18: 407 | T18: 382 | U18: 25.2 | V18: Blindage de fouille, paroi moulée, 400 mm
A19: 00.009 | B19: Baugrubensicherung, Schlitzwand, 800 mm | C19: 91.082 | D19: Entsorgung, Baugrubensicherung, Schlitzwand, 800mm | E19: - | F19: m2 | G19: 1230000 | H19: 1100000 | I19: 129000 | J19: 2410 | K19: 2140 | L19: 265 | M19: 136 | N19: 126 | O19: 9.43 | P19: 2270 | Q19: 2010 | R19: 256 | S19: 777 | T19: 728 | U19: 49.6 | V19: Blindage de fouille, paroi moulée, 800 mm
A20: 00.010 | B20: Baugrubensicherung, Spundwand, auskragend | C20: 91.083 | D20: Entsorgung, Baugrubensicherung, Spundwand, auskragend | E20: - | F20: m2 | G20: 228000 | H20: 228000 | I20: 0 | J20: 793 | K20: 793 | L20: 0 | M20: 46.2 | N20: 46.2 | O20: 0 | P20: 747 | Q20: 747 | R20: 0 | S20: 163 | T20: 163 | U20: 0 | V20: Blindage de fouille, paroi de palplanche, en porte-à-faux
A21: 00.011 | B21: Baugrubensicherung, Spundwand, gespriesst | C21: 91.084 | D21: Entsorgung, Baugrubensicherung, Spundwand, gespriesst | E21: - | F21: m2 | G21: 129000 | H21: 129000 | I21: 0 | J21: 446 | K21: 446 | L21: 0 | M21: 25.3 | N21: 25.3 | O21: 0 | P21: 421 | Q21: 421 | R21: 0 | S21: 92.3 | T21: 92.3 | U21: 0 | V21: Blindage de fouille, paroi de palplanche, étayé
A22: 00.012 | B22: Baugrubensicherung, Spundwand, verankert | C22: 91.085 | D22: Entsorgung, Baugrubensicherung, Spundwand, verankert | E22: - | F22: m2 | G22: 255000 | H22: 255000 | I22: 0 | J22: 868 | K22: 868 | L22: 0 | M22: 55.3 | N22: 55.3 | O22: 0 | P22: 813 | Q22: 813 | R22: 0 | S22: 181 | T22: 181 | U22: 0 | V22: Blindage de fouille, paroi de palplanche, fixe
... A34: 00.024 | B34: Wasserhaltung, Pumphöhe 10 m | C34: 91.097 | D34: Entsorgung, Wasserhaltung, Pumphöhe 10m | E34: - | F34: m3 | G34: 22.5 | H34: 22.5 | I34: 0 | J34: 0.19 | K34: 0.19 | L34: 0 | M34: 0.0309 | N34: 0.0309 | O34: 0 | P34: 0.159 | Q34: 0.159 | R34: 0 | S34: 0.00656 | T34: 0.00656 | U34: 0 | V34: Épuisement des eaux, hauteur de refoulement, 10 m
A35: 01 | B35: Beton | E35: kg/m3 | V35: Béton
A36: 1.001 | B36: Magerbeton (ohne Bewehrung) | C36: 91.061 | D36: Entsorgungsmix, Beton unbewehrt | E36: 2150 | F36: kg | G36: 65.1 | H36: 40.2 | I36: 24.9 | J36: 0.149 | K36: 0.0995 | L36: 0.049 | M36: 0.00923 | N36: 0.00727 | O36: 0.00196 | P36: 0.139 | Q36: 0.0922 | R36: 0.0471 | S36: 0.0591 | T36: 0.0503 | U36: 0.00881 | V36: Béton maigre (sans armature)
A37: 1.002 | B37: Hochbaubeton (ohne Bewehrung) | C37: 91.060 | D37: Entsorgungsmix, Beton bewehrt | E37: 2300 | F37: kg | G37: 94.3 | H37: 67.3 | I37: 27 | J37: 0.215 | K37: 0.159 | L37: 0.0554 | M37: 0.0134 | N37: 0.0115 | O37: 0.00198 | P37: 0.201 | Q37: 0.148 | R37: 0.0535 | S37: 0.0992 | T37: 0.0889 | U37: 0.0104 | V37: Béton pour bâtiment (sans armature)
A38: 1.003 | B38: Tiefbaubeton (ohne Bewehrung) | C38: 91.060 | D38: Entsorgungsmix, Beton bewehrt | E38: 2350 | F38: kg | G38: 99.9 | H38: 72.9 | I38: 27 | J38: 0.232 | K38: 0.176 | L38: 0.0554 | M38: 0.0144 | N38: 0.0125 | O38: 0.00198 | P38: 0.217 | Q38: 0.164 | R38: 0.0534 | S38: 0.107 | T38: 0.0964 | U38: 0.0104 | V38: Béton pour travaux de génie civil (sans armature)
A39: 1.004 | B39: Bohrpfahlbeton (ohne Bewehrung) | C39: 91.060 | D39: Entsorgungsmix, Beton bewehrt | E39: 2325 | F39: kg | G39: 106 | H39: 79 | I39: 26.9 | J39: 0.243 | K39: 0.188 | L39: 0.0553 | M39: 0.0155 | N39: 0.0135 | O39: 0.00198 | P39: 0.228 | Q39: 0.175 | R39: 0.0533 | S39: 0.117 | T39: 0.107 | U39: 0.0104 | V39: Béton pour pieux (sans armature)
A40: 01.041 | B40: Betonfertigteil, hochfester Beton, ab Werk | C40: 91.060 | D40: Entsorgungsmix, Beton bewehrt | E40: 2770 | F40: kg | G40: 477 | H40: 454 | I40: 23.8 | J40: 0.826 | K40: 0.777 | L40: 0.0489 | M40: 0.0574 | N40: 0.0556 | O40: 0.00175 | P40: 0.768 | Q40: 0.721 | R40: 0.0472 | S40: 0.265 | T40: 0.255 | U40: 0.00917 | V40: Élément préfabriqué en béton, béton à hautes performances, sortie d'usine
A41: 01.042 | B41: Betonfertigteil, Normalbeton, ab Werk | C41: 91.060 | D41: Entsorgungsmix, Beton bewehrt | E41: 2500 | F41: kg | G41: 245 | H41: 218 | I41: 26.1 | J41: 0.58 | K41: 0.526 | L41: 0.0535 | M41: 0.0961 | N41: 0.0942 | O41: 0.00191 | P41: 0.484 | Q41: 0.432 | R41: 0.0516 | S41: 0.172 | T41: 0.162 | U41: 0.01 | V41: Élément préfabriqué en béton, béton normal, sortie d'usine
A42: 01.043 | B42: Hanfbeton | C42: 91.073 | D42: Entsorgungsmix, Hanfbeton | E42: 600 | F42: kg | G42: 371 | H42: 370 | I42: 0.743 | J42: 1.87 | K42: 1.86 | L42: 0.0028 | M42: 0.882 | N42: 0.882 | O42: 2.59e-05 | P42: 0.984 | Q42: 0.982 | R42: 0.00278 | S42: 0.288 | T42: 0.288 | U42: 0.000365 | V42: Béton chaux-chanvre
A43: 01.043.01 | B43: Hanfbeton, ARBIO | C43: 91.073 | D43: Entsorgungsmix, Hanfbeton | E43: 600 | F43: kg | G43: 357 | H43: 356 | I43: 0.743 | J43: 1.8 | K43: 1.79 | L43: 0.0028 | M43: 0.849 | N43: 0.848 | O43: 2.59e-05 | P43: 0.947 | Q43: 0.944 | R43: 0.00278 | S43: 0.277 | T43: 0.277 | U43: 0.000365 | V43: Béton chaux-chanvre, ARBIO
A44: Betonsortenrechner: Mit dem Betonsortenrechner (http://treeze.ch/de/rechner/betonsortenrechner/) können die Umweltkennwerte von spezifischen Betonen mit verschiedenen Zementtypen und Gesteinskörnungen berechnet werden.
A45: Calculatrice à béton: la calculatrice (http://treeze.ch/de/rechner/betonsortenrechner/) permet de calculer les données environnementales des différents types de béton fabriqués à partir de ciments et granulats divers.
A46: 02 | B46: Mauersteine | E46: kg/m3 | V46: Pierres de taille
A47: 02.001 | B47: Backstein | C47: 91.059 | D47: Entsorgungsmix, Backstein | E47: 900 | F47: kg | G47: 217 | H47: 191 | I47: 25.8 | J47: 0.868 | K47: 0.816 | L47: 0.0523 | M47: 0.0775 | N47: 0.0757 | O47: 0.00177 | P47: 0.791 | Q47: 0.74 | R47: 0.0505 | S47: 0.258 | T47: 0.249 | U47: 0.00903 | V47: Brique en terre cuite
A48: 02.002 | B48: Kalksandstein | C48: 91.065 | D48: Entsorgungsmix, Kalksandstein | E48: 1400 | F48: kg | G48: 157 | H48: 132 | I48: 25.1 | J48: 0.434 | K48: 0.385 | L48: 0.0499 | M48: 0.0368 | N48: 0.035 | O48: 0.00186 | P48: 0.398 | Q48: 0.35 | R48: 0.0481 | S48: 0.138 | T48: 0.129 | U48: 0.00868 | V48: Grès
A49: 02.002.01 | B49: Kalksandstein, FBB | C49: 91.065 | D49: Entsorgungsmix, Kalksandstein | E49: 1400 | F49: kg | G49: 122 | H49: 97.4 | I49: 25.1 | J49: 0.35 | K49: 0.3 | L49: 0.0499 | M49: 0.0344 | N49: 0.0325 | O49: 0.00186 | P49: 0.316 | Q49: 0.267 | R49: 0.0481 | S49: 0.108 | T49: 0.0996 | U49: 0.00868 | V49: Grès, FBB
A50: 02.003 | B50: Leichtlehmstein | C50: 91.059 | D50: Entsorgungsmix, Backstein | E50: 700 | F50: kg | G50: 237 | H50: 212 | I50: 25.8 | J50: 1.56 | K50: 1.5 | L50: 0.0523 | M50: 0.793 | N50: 0.791 | O50: 0.00177 | P50: 0.762 | Q50: 0.712 | R50: 0.0505 | S50: 0.17 | T50: 0.161 | U50: 0.00903 | V50: Brique en argile léger
A51: 02.004 | B51: Leichtzementstein, Blähton | C51: 91.070 | D51: Entsorgungsmix, Zement (in Beton) und Mauermörtel | E51: 1200 | F51: kg | G51: 471 | H51: 445 | I51: 26.6 | J51: 1.57 | K51: 1.51 | L51: 0.0547 | M51: 0.0521 | N51: 0.0503 | O51: 0.00178 | P51: 1.51 | Q51: 1.46 | R51: 0.0529 | S51: 0.417 | T51: 0.407 | U51: 0.00961 | V51: Pierre en béton léger: argile expansée
A52: 02.005 | B52: Leichtzementstein, Naturbims | C52: 91.070 | D52: Entsorgungsmix, Zement (in Beton) und Mauermörtel | E52: 1200 | F52: kg | G52: 222 | H52: 195 | I52: 26.6 | J52: 0.455 | K52: 0.4 | L52: 0.0547 | M52: 0.0309 | N52: 0.0291 | O52: 0.00178 | P52: 0.424 | Q52: 0.371 | R52: 0.0529 | S52: 0.223 | T52: 0.214 | U52: 0.00961 | V52: Pierre en béton léger: pierre ponce naturelle
...

Sheet ImportGebäudetechnik
A1: Name | B1: ProductKey | C1: Description | D1: Picture | E1: Product sections | F1: Type | G1: SubType | H1: vyzn.catalogue.ch.minergie.eco.MepClassification | I1: vyzn.catalogue.Density | J1: vyzn.catalogue.ch.KBOB2022.UBPTotal | K1: vyzn.catalogue.ch.KBOB2022.UBPProduction | L1: vyzn.catalogue.ch.KBOB2022.UBPDisposal | M1: vyzn.catalogue.ch.KBOB2022.RenewableEnergyTotal | N1: vyzn.catalogue.ch.KBOB2022.RenewableEnergyProduction | O1: vyzn.catalogue.ch.KBOB2022.RenewableEnergyDisposal | P1: vyzn.catalogue.ch.KBOB2022.GreyEnergyTotal | Q1: vyzn.catalogue.ch.KBOB2022.GreyEnergyProduction | R1: vyzn.catalogue.ch.KBOB2022.GreyEnergyDisposal | S1: vyzn.catalogue.ch.KBOB2022.GHGEmissionsTotal | T1: vyzn.catalogue.ch.KBOB2022.GHGEmissionsProduction | U1: vyzn.catalogue.ch.KBOB2022.GHGEmissionsDisposal | V1: vyzn.catalogue.ch.KBOB2022.LCARefUnit | W1: vyzn.catalogue.ch.KBOB2022.LCARefDimension | X1: vyzn.catalogue.ch.KBOB2022.BiogenicCarbon | Y1: KBOB REF | Z1: vyzn.catalogue.SourceENV | AA1: categoryPath | AB1: vyzn.catalogue.lifeCycle
A2: 31.001 Wärmeerzeuger, spez. Leistungsbedarf 10 W/m2 (KBOB.2016) | B2: 31.001 Wärmeerzeuger, spez. Leistungsbedarf 10 W/m2 (KBOB.2016) | F2: BUILDING_TECHNOLOGY | G2: BUILDING_TECHNOLOGY_HEATING | H2: heatGeneration | J2: 1200.000000 | K2: 1190.000000 | L2: 10.600000 | M2: 0.236000 | N2: 0.236000 | O2: 0.000317 | P2: 2.280000 | Q2: 2.260000 | R2: 0.018100 | S2: 0.512000 | T2: 0.501000 | U2: 0.010900 | V2: m2 | W2: energyReferenceArea | X2: 0 | Y2: 31.001 | Z2: KBOB 2016 | AA2: Alle > GEBÄUDETECHNIK > kbob.admin.ch > KBOB / ecobau / IPB 2009/1:2016 | AB2: 20
A3: 31.002 Wärmeerzeuger, spez. Leistungsbedarf 30 W/m2 (KBOB.2016) | B3: 31.002 Wärmeerzeuger, spez. Leistungsbedarf 30 W/m2 (KBOB.2016) | F3: BUILDING_TECHNOLOGY | G3: BUILDING_TECHNOLOGY_HEATING | H3: heatGeneration | J3: 3590.000000 | K3: 3560.000000 | L3: 31.800000 | M3: 0.708000 | N3: 0.707000 | O3: 0.000952 | P3: 6.830000 | Q3: 6.780000 | R3: 0.054400 | S3: 1.530000 | T3: 1.500000 | U3: 0.032700 | V3: m2 | W3: energyReferenceArea | X3: 0 | Y3: 31.002 | Z3: KBOB 2016 | AA3: Alle > GEBÄUDETECHNIK > kbob.admin.ch > KBOB / ecobau / IPB 2009/1:2016 | AB3: 20
A4: 31.003 Wärmeerzeuger, spez. Leistungsbedarf 50 W/m2 (KBOB.2016) | B4: 31.003 Wärmeerzeuger, spez. Leistungsbedarf 50 W/m2 (KBOB.2016) | F4: BUILDING_TECHNOLOGY | G4: BUILDING_TECHNOLOGY_HEATING | H4: heatGeneration | J4: 5990.000000 | K4: 5930.000000 | L4: 53.000000 | M4: 1.180000 | N4: 1.180000 | O4: 0.001590 | P4: 11.400000 | Q4: 11.300000 | R4: 0.090600 | S4: 2.560000 | T4: 2.500000 | U4: 0.054500 | V4: m2 | W4: energyReferenceArea | X4: 0 | Y4: 31.003 | Z4: KBOB 2016 | AA4: Alle > GEBÄUDETECHNIK > kbob.admin.ch > KBOB / ecobau / IPB 2009/1:2016 | AB4: 20
